Workbook

Sheet Tong hop nhan su
A1: CÔNG TY CỔ PHẦN CHIẾU SÁNG CÔNG CỘNG TP.HCM
A2: CHIẾU SÁNG KHU VỰC TRUNG TÂM
D3: BẢNG TỔNG HỢP NHÂN SỰ & HỆ SỐ LƯƠNG NĂNG SUẤT - CSKVTT
D4: Cập nhật: tháng 6/2026 • Tổng số: 45 người • Hệ số tự tính theo Điểm năng suất (Bảng tra 2026)
A6: Stt | B6: MSNV | C6: Họ và tên | D6: Giới tính | E6: Ngày sinh | F6: Chức vụ | G6: Loại vị trí NS | H6: Điểm năng suất | I6: Xếp loại | J6: Hệ số lương NS | K6: Nhóm/Đội | L6: Khối | M6: Số CCCD | N6: Ngày cấp | O6: Nơi cấp CCCD | P6: Quê quán | Q6: Địa chỉ thường trú | R6: Địa chỉ tạm trú | S6: Bằng cấp, chuyên môn | T6: Số điện thoại | U6: Email | V6: Số thẻ BHYT | W6: Đảng viên
A7: 1 | B7: L2085 | C7: Mai Vũ Lâm | D7: Nam | E7: 15/07/1982 | F7: GĐ CSKVTT | G7: CN/NV thường | I7: =IF($H7="","",IF($H7>=90,"Xuất sắc (A+)",IF($H7>=85,"Giỏi (A)",IF($H7>=80,"Tốt (A-)",IF($H7>=75,"Khá (B+)",IF($H7>=70,"Khá (B)",IF($H7>=65,"Khá (B-)",IF($H7>=60,"Trung bình (C+)",IF($H7>=55,"Trung bình (C)",IF($H7>=50,"Yếu (D)","Không đạt (F)")))))))))) | J7: =IF($H7="","",INDEX(BangTra!$B$2:$D$11,MATCH($H7,BangTra!$A$2:$A$11,1),IF($G7="Đội trưởng",3,IF($G7="Đội phó",2,1)))) | K7: CSKV B | L7: Gián tiếp | M7: 074082002081 | N7: 25/04/2021 | O7: Cục trưởng cục cảnh sát - Quản lý hành chính về trật tự xã hội | P7: Bình Dương | Q7: 63/23A, Liên Khu 16-18, Bình Trị Đông, Bình Tân | S7: Kỹ sư Điện - Điện tử | T7: 0989725507 | V7: DN4790205173644 | W7: Đảng viên
A8: 2 | B8: H1930 | C8: MẠCH NGỌC HUY | D8: Nam | E8: 16/03/1971 | F8: P.GĐ CSKVTT | G8: CN/NV thường | I8: =IF($H8="","",IF($H8>=90,"Xuất sắc (A+)",IF($H8>=85,"Giỏi (A)",IF($H8>=80,"Tốt (A-)",IF($H8>=75,"Khá (B+)",IF($H8>=70,"Khá (B)",IF($H8>=65,"Khá (B-)",IF($H8>=60,"Trung bình (C+)",IF($H8>=55,"Trung bình (C)",IF($H8>=50,"Yếu (D)","Không đạt (F)")))))))))) | J8: =IF($H8="","",INDEX(BangTra!$B$2:$D$11,MATCH($H8,BangTra!$A$2:$A$11,1),IF($G8="Đội trưởng",3,IF($G8="Đội phó",2,1)))) | K8: CSKV TT | M8: 066071000720 | N8: 25/04/2021 | O8: Cục trưởng cục cảnh sát - Quản lý hành chính về trật tự xã hội | P8: Bến Tre | Q8: Số 018 Lô H Chung cư Nguyễn Thiện Thuật, phường 1, quận 3, Tp.HCM | S8: Kỹ sư công nghiệp ngành Công nghiệp nông thôn | T8: 0988530750 | V8: DN4790299047048 | W8: Đảng viên
A9: 3 | B9: H1830 | C9: LÊ VĂN HÙNG | D9: Nam | E9: 14/08/1970 | F9: GĐ XNCS Chợ Lớn | G9: CN/NV thường | I9: =IF($H9="","",IF($H9>=90,"Xuất sắc (A+)",IF($H9>=85,"Giỏi (A)",IF($H9>=80,"Tốt (A-)",IF($H9>=75,"Khá (B+)",IF($H9>=70,"Khá (B)",IF($H9>=65,"Khá (B-)",IF($H9>=60,"Trung bình (C+)",IF($H9>=55,"Trung bình (C)",IF($H9>=50,"Yếu (D)","Không đạt (F)")))))))))) | J9: =IF($H9="","",INDEX(BangTra!$B$2:$D$11,MATCH($H9,BangTra!$A$2:$A$11,1),IF($G9="Đội trưởng",3,IF($G9="Đội phó",2,1)))) | K9: CSKV TT | M9: 082070000970 | N9: 07/04/2021 | O9: Cục trưởng cục cảnh sát - Quản lý hành chính về trật tự xã hội | P9: Tiền Giang | Q9: Số B1-19-01, Chung cư CityGate - Số 15 Võ Văn Kiệt, phường 16, quận 8, Tp.HCM | S9: Cử nhân Quản trị Kinh doanh, Kỹ sư Điện - Điện tử - Ngành Điện năng | T9: 0909611868 | V9: DN4790298103351
A10: 4 | B10: T3205 | C10: LÊ TÔN QUANG THỨC | D10: Nam | E10: 16/09/1979 | F10: GĐ BKHĐT | G10: CN/NV thường | I10: =IF($H10="","",IF($H10>=90,"Xuất sắc (A+)",IF($H10>=85,"Giỏi (A)",IF($H10>=80,"Tốt (A-)",IF($H10>=75,"Khá (B+)",IF($H10>=70,"Khá (B)",IF($H10>=65,"Khá (B-)",IF($H10>=60,"Trung bình (C+)",IF($H10>=55,"Trung bình (C)",IF($H10>=50,"Yếu (D)","Không đạt (F)")))))))))) | J10: =IF($H10="","",INDEX(BangTra!$B$2:$D$11,MATCH($H10,BangTra!$A$2:$A$11,1),IF($G10="Đội trưởng",3,IF($G10="Đội phó",2,1)))) | K10: CSKV TT | M10: 051079000041 | N10: 22/12/2021 | O10: Cục trưởng cục cảnh sát - Quản lý hành chính về trật tự xã hội | P10: Quảng Ngãi | Q10: Số 2683A/9B, đường Phạm Thế Hiển, phường 7, quận 8, Tp.HCM | S10: Kỹ sư Điện ngành điện công nghiệp | T10: 0989365522 | V10: DN4790205173648
A11: 5 | B11: L2235 | C11: TRẦN HỮU LƯU | D11: Nam | E11: 20/07/1971 | F11: GĐ XNCS Sài Gòn | G11: CN/NV thường | I11: =IF($H11="","",IF($H11>=90,"Xuất sắc (A+)",IF($H11>=85,"Giỏi (A)",IF($H11>=80,"Tốt (A-)",IF($H11>=75,"Khá (B+)",IF($H11>=70,"Khá (B)",IF($H11>=65,"Khá (B-)",IF($H11>=60,"Trung bình (C+)",IF($H11>=55,"Trung bình (C)",IF($H11>=50,"Yếu (D)","Không đạt (F)")))))))))) | J11: =IF($H11="","",INDEX(BangTra!$B$2:$D$11,MATCH($H11,BangTra!$A$2:$A$11,1),IF($G11="Đội trưởng",3,IF($G11="Đội phó",2,1)))) | K11: CSKV TT | M11: 044071009619 | N11: 10/02/2022 | O11: Cục trưởng cục cảnh sát - Quản lý hành chính về trật tự xã hội | P11: Quảng Bình | Q11: Số 2A, Đường số 44, phường Hiệp Bình Chánh, Thành phố Thủ Đức, Tp.HCM | R11: Số 417/49/96, đường Quang Trung, phường 10, quận Gò Vấp, Tp.HCM | S11: Kỹ sư ngành điện kỹ thuật | T11: 0914287419 | V11: DN4790205173649
A12: 6 | B12: H1840 | C12: LÊ VĂN HÙNG | D12: Nam | E12: 22/08/1981 | F12: Cán sự | G12: CN/NV thường | I12: =IF($H12="","",IF($H12>=90,"Xuất sắc (A+)",IF($H12>=85,"Giỏi (A)",IF($H12>=80,"Tốt (A-)",IF($H12>=75,"Khá (B+)",IF($H12>=70,"Khá (B)",IF($H12>=65,"Khá (B-)",IF($H12>=60,"Trung bình (C+)",IF($H12>=55,"Trung bình (C)",IF($H12>=50,"Yếu (D)","Không đạt (F)")))))))))) | J12: =IF($H12="","",INDEX(BangTra!$B$2:$D$11,MATCH($H12,BangTra!$A$2:$A$11,1),IF($G12="Đội trưởng",3,IF($G12="Đội phó",2,1)))) | K12: CSKV TT | M12: 172161582 | N12: 19/01/2016 | O12: CA Thanh Hóa | P12: Thanh Hoá | Q12: Xã Triêu Dương, huyện Tĩnh Gia, tỉnh Thanh Hóa (Số 331/12A Trần Xuân Soạn, phường Tân Kiểng, Quận 7 chưa xác nhận lại thẻ CCCD) | S12: Cử nhân Cao đẳng ngành điện công nghiệp | T12: 0974749700 | V12: DN4790204008660
A13: 7 | B13: N2400 | C13: NGUYỄN QUANG NGHĨA | D13: Nam | E13: 25/12/1982 | F13: CHUYÊN VIÊN | G13: CN/NV thường | I13: =IF($H13="","",IF($H13>=90,"Xuất sắc (A+)",IF($H13>=85,"Giỏi (A)",IF($H13>=80,"Tốt (A-)",IF($H13>=75,"Khá (B+)",IF($H13>=70,"Khá (B)",IF($H13>=65,"Khá (B-)",IF($H13>=60,"Trung bình (C+)",IF($H13>=55,"Trung bình (C)",IF($H13>=50,"Yếu (D)","Không đạt (F)")))))))))) | J13: =IF($H13="","",INDEX(BangTra!$B$2:$D$11,MATCH($H13,BangTra!$A$2:$A$11,1),IF($G13="Đội trưởng",3,IF($G13="Đội phó",2,1)))) | K13: CSKV TT | M13: 036082028338 | N13: 10/08/2021 | O13: Cục trưởng cục cảnh sát - Quản lý hành chính về trật tự xã hội | P13: Thái Bình | Q13: Số 225/34, đường Thoại Ngọc Thầu, phường Phú Thạnh, quận Tân Phú, Tp.HCM | S13: Kỹ sư ngành điện công nghiệp | T13: 0985579536 | V13: DN4797909175633
A14: 8 | B14: T4245 | C14: PHẠM VĂN TÍNH | D14: Nam | E14: 11/09/1990 | F14: CÔNG NHÂN | G14: CN/NV thường | I14: =IF($H14="","",IF($H14>=90,"Xuất sắc (A+)",IF($H14>=85,"Giỏi (A)",IF($H14>=80,"Tốt (A-)",IF($H14>=75,"Khá (B+)",IF($H14>=70,"Khá (B)",IF($H14>=65,"Khá (B-)",IF($H14>=60,"Trung bình (C+)",IF($H14>=55,"Trung bình (C)",IF($H14>=50,"Yếu (D)","Không đạt (F)")))))))))) | J14: =IF($H14="","",INDEX(BangTra!$B$2:$D$11,MATCH($H14,BangTra!$A$2:$A$11,1),IF($G14="Đội trưởng",3,IF($G14="Đội phó",2,1)))) | K14: CSKV TT | M14: 371341014 | N14: 25/03/2019 | O14: CA Kiên Giang | P14: Kiên Giang | Q14: Ấp Kinh I, xã Hòa Điền, huyện Kiên Lương, tỉnh Kiên Giang | R14: Số E12/355G, Quốc Lộ 50, Ấp 5, xã Phong Phú, huyện Bình Chánh, Tp.HCM | S14: Kỹ sư Công nghệ kỹ thuật Điện, điện tử | T14: 0763968388 | V14: DN4797913099831
A15: 9 | B15: V3600 | C15: PHẠM TẤN VIỆT | D15: Nam | E15: 14/05/1976 | F15: CHUYÊN VIÊN | G15: CN/NV thường | I15: =IF($H15="","",IF($H15>=90,"Xuất sắc (A+)",IF($H15>=85,"Giỏi (A)",IF($H15>=80,"Tốt (A-)",IF($H15>=75,"Khá (B+)",IF($H15>=70,"Khá (B)",IF($H15>=65,"Khá (B-)",IF($H15>=60,"Trung bình (C+)",IF($H15>=55,"Trung bình (C)",IF($H15>=50,"Yếu (D)","Không đạt (F)")))))))))) | J15: =IF($H15="","",INDEX(BangTra!$B$2:$D$11,MATCH($H15,BangTra!$A$2:$A$11,1),IF($G15="Đội trưởng",3,IF($G15="Đội phó",2,1)))) | K15: CSKV TT | M15: 091076002553 | N15: 13/02/2022 | O15: Cục trưởng cục cảnh sát - Quản lý hành chính về trật tự xã hội | P15: Kiên Giang | Q15: Tổ 1, KP Kiên Tân, Thị trấn Kiên Lương, tỉnh Kiên Giang | R15: Số 001 C1 Chung cư Ba Tơ, phường 7, quận 8, Tp.HCM | S15: Kỹ sư ngành điện-điện tử | T15: 0938678477 | V15: DN4797909175636
A16: 10 | B16: P4250 | C16: LÊ HỒNG PHÚC | D16: Nam | E16: 29/09/1992 | F16: CHUYÊN VIÊN | G16: CN/NV thường | I16: =IF($H16="","",IF($H16>=90,"Xuất sắc (A+)",IF($H16>=85,"Giỏi (A)",IF($H16>=80,"Tốt (A-)",IF($H16>=75,"Khá (B+)",IF($H16>=70,"Khá (B)",IF($H16>=65,"Khá (B-)",IF($H16>=60,"Trung bình (C+)",IF($H16>=55,"Trung bình (C)",IF($H16>=50,"Yếu (D)","Không đạt (F)")))))))))) | J16: =IF($H16="","",INDEX(BangTra!$B$2:$D$11,MATCH($H16,BangTra!$A$2:$A$11,1),IF($G16="Đội trưởng",3,IF($G16="Đội phó",2,1)))) | K16: CSKV TT | M16: 312186952 | N16: 12/07/2010 | O16: CA Tiền Giang | P16: Tiền Giang | Q16: Ấp Kinh trên, xã Bình Ân, huyện Gò Công, tỉnh Tiền Giang | S16: Cao đẳng Công nghệ kỹ thuật điện, điện tử | T16: 0908591556 | V16: DN4797915232641
A17: 11 | B17: A1015 | C17: TRƯƠNG THÀNH AN | D17: Nam | E17: 22/09/1987 | F17: CÁN SỰ | G17: CN/NV thường | I17: =IF($H17="","",IF($H17>=90,"Xuất sắc (A+)",IF($H17>=85,"Giỏi (A)",IF($H17>=80,"Tốt (A-)",IF($H17>=75,"Khá (B+)",IF($H17>=70,"Khá (B)",IF($H17>=65,"Khá (B-)",IF($H17>=60,"Trung bình (C+)",IF($H17>=55,"Trung bình (C)",IF($H17>=50,"Yếu (D)","Không đạt (F)")))))))))) | J17: =IF($H17="","",INDEX(BangTra!$B$2:$D$11,MATCH($H17,BangTra!$A$2:$A$11,1),IF($G17="Đội trưởng",3,IF($G17="Đội phó",2,1)))) | K17: CSKV TT | M17: 080087000787 | N17: 08/04/2021 | O17: Cục trưởng cục cảnh sát - Quản lý hành chính về trật tự xã hội | P17: Long An | Q17: Số 120 Khu phố 3, Thị Trấn Đông Thành, huyện Đức Huệ, tỉnh Long An | S17: Cao đẳng ngành Điện tử - Viễn thông | T17: 0937386262 | V17: DN4797912144045
A18: 12 | B18: L2220 | C18: CHÂU THÀNH LUÂN | D18: Nam | E18: 10/12/1988 | F18: CÁN SỰ | G18: CN/NV thường | I18: =IF($H18="","",IF($H18>=90,"Xuất sắc (A+)",IF($H18>=85,"Giỏi (A)",IF($H18>=80,"Tốt (A-)",IF($H18>=75,"Khá (B+)",IF($H18>=70,"Khá (B)",IF($H18>=65,"Khá (B-)",IF($H18>=60,"Trung bình (C+)",IF($H18>=55,"Trung bình (C)",IF($H18>=50,"Yếu (D)","Không đạt (F)")))))))))) | J18: =IF($H18="","",INDEX(BangTra!$B$2:$D$11,MATCH($H18,BangTra!$A$2:$A$11,1),IF($G18="Đội trưởng",3,IF($G18="Đội phó",2,1)))) | K18: CSKV TT | M18: 215039274 | N18: 12/02/2011 | O18: CA Bình Định | P18: Bình Định | Q18: Thôn Dĩnh Thạnh, Xã Tam Quan Bắc, huyện Hoài Nhơn, tỉnh Bình Định | S18: Cao đẳng ngành tin học (Mạng máy tính) | T18: 0934093219 | V18: DN4797912232327
A19: 13 | B19: D1340 | C19: ĐỖ TIẾN ĐẠT | D19: Nam | E19: 10/12/1973 | F19: CÔNG NHÂN | G19: CN/NV thường | I19: =IF($H19="","",IF($H19>=90,"Xuất sắc (A+)",IF($H19>=85,"Giỏi (A)",IF($H19>=80,"Tốt (A-)",IF($H19>=75,"Khá (B+)",IF($H19>=70,"Khá (B)",IF($H19>=65,"Khá (B-)",IF($H19>=60,"Trung bình (C+)",IF($H19>=55,"Trung bình (C)",IF($H19>=50,"Yếu (D)","Không đạt (F)")))))))))) | J19: =IF($H19="","",INDEX(BangTra!$B$2:$D$11,MATCH($H19,BangTra!$A$2:$A$11,1),IF($G19="Đội trưởng",3,IF($G19="Đội phó",2,1)))) | K19: CSKV TT | M19: 079073033879 | N19: 17/08/2021 | O19: Cục trưởng cục cảnh sát - Quản lý hành chính về trật tự xã hội | P19: Quảng Ngãi | Q19: Số 84/24/1, đường Trần Hữu Trang, phường 10, quận Phú Nhuận, Tp.HCM | S19: Cao đẳng nghề điện tử công nghiệp | T19: 0938383450 | V19: DN4797909175641
A20: 14 | B20: C1305 | C20: PHẠM XUÂN CƯỜNG | D20: Nam | E20: 02/08/1972 | F20: CÔNG NHÂN | G20: CN/NV thường | I20: =IF($H20="","",IF($H20>=90,"Xuất sắc (A+)",IF($H20>=85,"Giỏi (A)",IF($H20>=80,"Tốt (A-)",IF($H20>=75,"Khá (B+)",IF($H20>=70,"Khá (B)",IF($H20>=65,"Khá (B-)",IF($H20>=60,"Trung bình (C+)",IF($H20>=55,"Trung bình (C)",IF($H20>=50,"Yếu (D)","Không đạt (F)")))))))))) | J20: =IF($H20="","",INDEX(BangTra!$B$2:$D$11,MATCH($H20,BangTra!$A$2:$A$11,1),IF($G20="Đội trưởng",3,IF($G20="Đội phó",2,1)))) | K20: CSKV TT | M20: 079072022606 | N20: 29/04/2021 | O20: Cục trưởng cục cảnh sát - Quản lý hành chính về trật tự xã hội | P20: Hà Nội | Q20: Số 372 Lầu 2, đường Bạch Đằng, phường 14, quận Bình Thạnh, Tp.HCM | S20: Cao đẳng nghề điện tử công nghiệp | T20: 0913149547 | V20: DN4790201127852
A21: 15 | B21: H1860 | C21: NGUYỄN TRẦN HÙNG | D21: Nam | E21: 08/09/1971 | F21: CÔNG NHÂN | G21: CN/NV thường | I21: =IF($H21="","",IF($H21>=90,"Xuất sắc (A+)",IF($H21>=85,"Giỏi (A)",IF($H21>=80,"Tốt (A-)",IF($H21>=75,"Khá (B+)",IF($H21>=70,"Khá (B)",IF($H21>=65,"Khá (B-)",IF($H21>=60,"Trung bình (C+)",IF($H21>=55,"Trung bình (C)",IF($H21>=50,"Yếu (D)","Không đạt (F)")))))))))) | J21: =IF($H21="","",INDEX(BangTra!$B$2:$D$11,MATCH($H21,BangTra!$A$2:$A$11,1),IF($G21="Đội trưởng",3,IF($G21="Đội phó",2,1)))) | K21: CSKV TT | M21: 079071009720 | N21: 25/04/2021 | O21: Cục trưởng cục cảnh sát - Quản lý hành chính về trật tự xã hội | P21: Tp.HCM | Q21: Số 115/17A, đường Hưng Phú, phường 8, quận 8, Tp.HCM | S21: Cao đẳng nghề điện tử công nghiệp | T21: 0908477047 | V21: DN4790298103352
A22: 16 | B22: V3605 | C22: NGUYỄN BÁ VINH | D22: Nam | E22: 27/03/1982 | F22: CÔNG NHÂN | G22: CN/NV thường | I22: =IF($H22="","",IF($H22>=90,"Xuất sắc (A+)",IF($H22>=85,"Giỏi (A)",IF($H22>=80,"Tốt (A-)",IF($H22>=75,"Khá (B+)",IF($H22>=70,"Khá (B)",IF($H22>=65,"Khá (B-)",IF($H22>=60,"Trung bình (C+)",IF($H22>=55,"Trung bình (C)",IF($H22>=50,"Yếu (D)","Không đạt (F)")))))))))) | J22: =IF($H22="","",INDEX(BangTra!$B$2:$D$11,MATCH($H22,BangTra!$A$2:$A$11,1),IF($G22="Đội trưởng",3,IF($G22="Đội phó",2,1)))) | K22: CSKV TT | M22: 023476688 | N22: 21/03/2013 | O22: CA TP.HCM | P22: Tp.HCM | Q22: Số 139/14, đường Lạc Long Quân, phường 09, quận Tân Bình, Tp.HCM | S22: Cao Đẳng nghề Điện tử công nghiệp | T22: 0989307978 | V22: DN4790205187079
A23: 17 | B23: B1110 | C23: BÙI VĂN BÌNH | D23: Nam | E23: 12/03/1983 | F23: CÔNG NHÂN | G23: CN/NV thường | I23: =IF($H23="","",IF($H23>=90,"Xuất sắc (A+)",IF($H23>=85,"Giỏi (A)",IF($H23>=80,"Tốt (A-)",IF($H23>=75,"Khá (B+)",IF($H23>=70,"Khá (B)",IF($H23>=65,"Khá (B-)",IF($H23>=60,"Trung bình (C+)",IF($H23>=55,"Trung bình (C)",IF($H23>=50,"Yếu (D)","Không đạt (F)")))))))))) | J23: =IF($H23="","",INDEX(BangTra!$B$2:$D$11,MATCH($H23,BangTra!$A$2:$A$11,1),IF($G23="Đội trưởng",3,IF($G23="Đội phó",2,1)))) | K23: CSKV TT | M23: 025124268 | N23: 08/05/2009 | O23: CA TP.HCM | P23: Thái Bình | Q23: Số 3/1, đường Nguyễn Văn Lượng, phường 16, quận Gò Vấp, Tp.HCM | S23: Cao Đẳng nghề điện tử công nghiệp | T23: 0938898429 | V23: DN4790203223957
A24: 18 | B24: T3075 | C24: NGUYỄN TRỌNG THI | D24: Nam | E24: 19/12/1983 | F24: CÔNG NHÂN | G24: CN/NV thường | I24: =IF($H24="","",IF($H24>=90,"Xuất sắc (A+)",IF($H24>=85,"Giỏi (A)",IF($H24>=80,"Tốt (A-)",IF($H24>=75,"Khá (B+)",IF($H24>=70,"Khá (B)",IF($H24>=65,"Khá (B-)",IF($H24>=60,"Trung bình (C+)",IF($H24>=55,"Trung bình (C)",IF($H24>=50,"Yếu (D)","Không đạt (F)")))))))))) | J24: =IF($H24="","",INDEX(BangTra!$B$2:$D$11,MATCH($H24,BangTra!$A$2:$A$11,1),IF($G24="Đội trưởng",3,IF($G24="Đội phó",2,1)))) | K24: CSKV TT | M24: 079083041174 | N24: 12/08/2021 | O24: Cục trưởng cục cảnh sát - Quản lý hành chính về trật tự xã hội | P24: Hải Phòng | Q24: Số 23/12A, đường Đinh Tiên Hoàng, phường 3, quận Bình Thạnh, Tp.HCM | R24: Số 9 Lầu 2 Tân Hàng, phường 10, quận 5, Tp.HCM | S24: Cao đẳng nghề điện tử công nghiệp; Trung học chuyên nghiệp ngành Kế toán | T24: 0822102102 | V24: DN4790205187078
A25: 19 | B25: T2880 | C25: VÕ MINH TÀI | D25: Nam | E25: 02/01/1985 | F25: CÔNG NHÂN | G25: CN/NV thường | I25: =IF($H25="","",IF($H25>=90,"Xuất sắc (A+)",IF($H25>=85,"Giỏi (A)",IF($H25>=80,"Tốt (A-)",IF($H25>=75,"Khá (B+)",IF($H25>=70,"Khá (B)",IF($H25>=65,"Khá (B-)",IF($H25>=60,"Trung bình (C+)",IF($H25>=55,"Trung bình (C)",IF($H25>=50,"Yếu (D)","Không đạt (F)")))))))))) | J25: =IF($H25="","",INDEX(BangTra!$B$2:$D$11,MATCH($H25,BangTra!$A$2:$A$11,1),IF($G25="Đội trưởng",3,IF($G25="Đội phó",2,1)))) | K25: CSKV TT | M25: 080085012600 | N25: 22/11/2021 | O25: Cục trưởng cục cảnh sát - Quản lý hành chính về trật tự xã hội | P25: Long An | Q25: Khu 3, Ấp Chánh Long Hiệp, huyện Bến Lức, tỉnh Long An | S25: Bằng nghề 3/7 điện công nghiệp | T25: 0908329738 | V25: DN4797909175634
A26: 20 | B26: A1025 | C26: TRẦN VĂN ÂN | D26: Nam | E26: 25/11/1983 | F26: CÔNG NHÂN | G26: CN/NV thường | I26: =IF($H26="","",IF($H26>=90,"Xuất sắc (A+)",IF($H26>=85,"Giỏi (A)",IF($H26>=80,"Tốt (A-)",IF($H26>=75,"Khá (B+)",IF($H26>=70,"Khá (B)",IF($H26>=65,"Khá (B-)",IF($H26>=60,"Trung bình (C+)",IF($H26>=55,"Trung bình (C)",IF($H26>=50,"Yếu (D)","Không đạt (F)")))))))))) | J26: =IF($H26="","",INDEX(BangTra!$B$2:$D$11,MATCH($H26,BangTra!$A$2:$A$11,1),IF($G26="Đội trưởng",3,IF($G26="Đội phó",2,1)))) | K26: CSKV TT | M26: 290706150 | N26: 14/08/2012 | O26: CA Tây Ninh | P26: Tây Ninh | Q26: Ấp Tân Thanh, Xã Tân Bình, huyện Tân Biên, tỉnh Tây Ninh | R26: Số 51/418, đường số 18B, KP1, Tổ 5, phường Bình Hưng Hoà A, quận Bình Tân, Tp.HCM | S26: Bằng nghề 3/7 điện công nghiệp | T26: 0593904520 | V26: DN4790205282801
A27: 21 | B27: T2845 | C27: HỒ TẤN TÀI | D27: Nam | E27: 19/03/1979 | F27: CÔNG NHÂN | G27: CN/NV thường | I27: =IF($H27="","",IF($H27>=90,"Xuất sắc (A+)",IF($H27>=85,"Giỏi (A)",IF($H27>=80,"Tốt (A-)",IF($H27>=75,"Khá (B+)",IF($H27>=70,"Khá (B)",IF($H27>=65,"Khá (B-)",IF($H27>=60,"Trung bình (C+)",IF($H27>=55,"Trung bình (C)",IF($H27>=50,"Yếu (D)","Không đạt (F)")))))))))) | J27: =IF($H27="","",INDEX(BangTra!$B$2:$D$11,MATCH($H27,BangTra!$A$2:$A$11,1),IF($G27="Đội trưởng",3,IF($G27="Đội phó",2,1)))) | K27: CSKV TT | M27: 079079000622 | N27: 09/05/2021 | O27: Cục trưởng cục cảnh sát - Quản lý hành chính về trật tự xã hội | P27: Quảng Nam | Q27: Số 76, đường Phan Đăng Lưu, phường 5, quận Phú Nhuận, Tp.HCM | R27: Số 74/3/11A, đường Phan Đăng Lưu, phường 5, quận Phú Nhuận, Tp.HCM | S27: Bằng nghề 3/7 Điện tử | T27: 0932598282 | V27: DN4797908446745
A28: 22 | B28: T3215 | C28: TRẦN THANH THỦY | D28: Nam | E28: 16/09/1969 | F28: NHÂN VIÊN | G28: CN/NV thường | I28: =IF($H28="","",IF($H28>=90,"Xuất sắc (A+)",IF($H28>=85,"Giỏi (A)",IF($H28>=80,"Tốt (A-)",IF($H28>=75,"Khá (B+)",IF($H28>=70,"Khá (B)",IF($H28>=65,"Khá (B-)",IF($H28>=60,"Trung bình (C+)",IF($H28>=55,"Trung bình (C)",IF($H28>=50,"Yếu (D)","Không đạt (F)")))))))))) | J28: =IF($H28="","",INDEX(BangTra!$B$2:$D$11,MATCH($H28,BangTra!$A$2:$A$11,1),IF($G28="Đội trưởng",3,IF($G28="Đội phó",2,1)))) | K28: CSKV TT | M28: 030069012944 | N28: 10/08/2021 | O28: Cục trưởng cục cảnh sát - Quản lý hành chính về trật tự xã hội | P28: Hải Dương | Q28: Số 211 Lô A2, Chung cư Thạnh Mỹ Lợi, phường Thạnh Mỹ Lợi, Thủ Đức, Tp.HCM | S28: Kỹ thuật viên ngành điện-điện tử CN (1 năm) | T28: 0989100845 | V28: DN4790296242101
A29: 23 | B29: H1980 | C29: CHUNG HOÀNG HUYNH | D29: Nam | E29: 21/01/1985 | F29: Phụ trách kho | G29: CN/NV thường | I29: =IF($H29="","",IF($H29>=90,"Xuất sắc (A+)",IF($H29>=85,"Giỏi (A)",IF($H29>=80,"Tốt (A-)",IF($H29>=75,"Khá (B+)",IF($H29>=70,"Khá (B)",IF($H29>=65,"Khá (B-)",IF($H29>=60,"Trung bình (C+)",IF($H29>=55,"Trung bình (C)",IF($H29>=50,"Yếu (D)","Không đạt (F)")))))))))) | J29: =IF($H29="","",INDEX(BangTra!$B$2:$D$11,MATCH($H29,BangTra!$A$2:$A$11,1),IF($G29="Đội trưởng",3,IF($G29="Đội phó",2,1)))) | K29: CSKV TT | M29: 096085000211 | N29: 22/11/2021 | O29: Cục trưởng cục cảnh sát - Quản lý hành chính về trật tự xã hội | P29: Cà Mau | Q29: Số 14/1A, đường Mai Hắc Đế, phường 15, quận 8, Tp.HCM | S29: Trung cấp chuyên nghiệp Sửa chữa khai thác thiết bị cơ khí ô tô; Chứng chỉ sơ cấp nghề Kỹ thuật điện (Trường cao đẳng điện lực) | T29: 0947784899 | V29: DN4797910300162
A30: 24 | B30: P2605 | C30: TRẦN CAO PHƯỚC | D30: Nam | E30: 05/06/1979 | F30: CÔNG NHÂN | G30: CN/NV thường | I30: =IF($H30="","",IF($H30>=90,"Xuất sắc (A+)",IF($H30>=85,"Giỏi (A)",IF($H30>=80,"Tốt (A-)",IF($H30>=75,"Khá (B+)",IF($H30>=70,"Khá (B)",IF($H30>=65,"Khá (B-)",IF($H30>=60,"Trung bình (C+)",IF($H30>=55,"Trung bình (C)",IF($H30>=50,"Yếu (D)","Không đạt (F)")))))))))) | J30: =IF($H30="","",INDEX(BangTra!$B$2:$D$11,MATCH($H30,BangTra!$A$2:$A$11,1),IF($G30="Đội trưởng",3,IF($G30="Đội phó",2,1)))) | K30: CSKV TT | M30: 079079006629 | N30: 25/02/2022 | O30: Cục trưởng cục cảnh sát - Quản lý hành chính về trật tự xã hội | P30: Tp.HCM | Q30: Số 38/3, đường Trần Xuân Soạn, phường Tân Kiểng, quận 7, Tp.HCM | S30: Trung học chuyên nghiệp ngành điện Công nghiệp và dân dụng | T30: 0908234905 0911236455 | V30: DN4790204330775
A31: 25 | B31: T3225 | C31: NGUYỄN QUÍ TIÊN | D31: Nam | E31: 04/07/1985 | F31: CÔNG NHÂN | G31: CN/NV thường | I31: =IF($H31="","",IF($H31>=90,"Xuất sắc (A+)",IF($H31>=85,"Giỏi (A)",IF($H31>=80,"Tốt (A-)",IF($H31>=75,"Khá (B+)",IF($H31>=70,"Khá (B)",IF($H31>=65,"Khá (B-)",IF($H31>=60,"Trung bình (C+)",IF($H31>=55,"Trung bình (C)",IF($H31>=50,"Yếu (D)","Không đạt (F)")))))))))) | J31: =IF($H31="","",INDEX(BangTra!$B$2:$D$11,MATCH($H31,BangTra!$A$2:$A$11,1),IF($G31="Đội trưởng",3,IF($G31="Đội phó",2,1)))) | K31: CSKV TT | M31: 311865808 | N31: 16/03/2019 | O31: CA Tiền Giang | P31: Tiền Giang | Q31: Ấp Mỹ Quới, Xã Hậu Mỹ Phú, huyện Cái Bè, tỉnh Tiền Giang | S31: Trung học chuyên nghiệp ngành Kỹ thuật nhiệt và điện, chuyên ngành Điện công nghiệp và dân dụng | T31: 0938588799 | V31: DN4797909175635
A32: 26 | B32: H1885 | C32: TRƯƠNG KHÁNH HÙNG | D32: Nam | E32: 29/02/1968 | F32: CÔNG NHÂN | G32: CN/NV thường | I32: =IF($H32="","",IF($H32>=90,"Xuất sắc (A+)",IF($H32>=85,"Giỏi (A)",IF($H32>=80,"Tốt (A-)",IF($H32>=75,"Khá (B+)",IF($H32>=70,"Khá (B)",IF($H32>=65,"Khá (B-)",IF($H32>=60,"Trung bình (C+)",IF($H32>=55,"Trung bình (C)",IF($H32>=50,"Yếu (D)","Không đạt (F)")))))))))) | J32: =IF($H32="","",INDEX(BangTra!$B$2:$D$11,MATCH($H32,BangTra!$A$2:$A$11,1),IF($G32="Đội trưởng",3,IF($G32="Đội phó",2,1)))) | K32: CSKV TT | M32: 079068006225 | N32: 28/03/2021 | O32: Cục trưởng cục cảnh sát - Quản lý hành chính về trật tự xã hội | P32: Sài Gòn | Q32: Số 119, đường Phạm Văn Chí, phường 1, quận 6, Tp.HCM | S32: Chứng chỉ sơ cấp ngành Hệ thống điện công nghiệp | T32: 0934389938 | V32: DN4790296242095
A33: 27 | B33: C1175 | C33: PHẠM MINH CHÁNH | D33: Nam | E33: 15/04/1974 | F33: CÔNG NHÂN | G33: CN/NV thường | I33: =IF($H33="","",IF($H33>=90,"Xuất sắc (A+)",IF($H33>=85,"Giỏi (A)",IF($H33>=80,"Tốt (A-)",IF($H33>=75,"Khá (B+)",IF($H33>=70,"Khá (B)",IF($H33>=65,"Khá (B-)",IF($H33>=60,"Trung bình (C+)",IF($H33>=55,"Trung bình (C)",IF($H33>=50,"Yếu (D)","Không đạt (F)")))))))))) | J33: =IF($H33="","",INDEX(BangTra!$B$2:$D$11,MATCH($H33,BangTra!$A$2:$A$11,1),IF($G33="Đội trưởng",3,IF($G33="Đội phó",2,1)))) | K33: CSKV TT | M33: 079074012615 | N33: 03/01/2020 | O33: Cục trưởng cục cảnh sát - Quản lý hành chính về trật tự xã hội | P33: Bình Dương | Q33: Số 185/10, đường Lê Quang Định, phường 7, quận Bình Thạnh, Tp.HCM | S33: Chứng chỉ sơ cấp ngành Hệ thống điện công nghiệp | T33: 0909213926 | V33: DN4790205187076
A34: 28 | B34: T4165 | C34: HỒ PHÚ TRƯỜNG | D34: Nam | E34: 29/03/1976 | F34: CÔNG NHÂN | G34: CN/NV thường | I34: =IF($H34="","",IF($H34>=90,"Xuất sắc (A+)",IF($H34>=85,"Giỏi (A)",IF($H34>=80,"Tốt (A-)",IF($H34>=75,"Khá (B+)",IF($H34>=70,"Khá (B)",IF($H34>=65,"Khá (B-)",IF($H34>=60,"Trung bình (C+)",IF($H34>=55,"Trung bình (C)",IF($H34>=50,"Yếu (D)","Không đạt (F)")))))))))) | J34: =IF($H34="","",INDEX(BangTra!$B$2:$D$11,MATCH($H34,BangTra!$A$2:$A$11,1),IF($G34="Đội trưởng",3,IF($G34="Đội phó",2,1)))) | K34: CSKV TT | M34: 079076001607 | N34: 13/06/2016 | O34: Cục trưởng cục cảnh sát - Quản lý hành chính về trật tự xã hội | P34: Vĩnh Long | Q34: Số 90, đường Nguyễn Trường Tộ, phường 12, quận 4, Tp.HCM | S34: Chứng chỉ sơ cấp ngành Hệ thống điện công nghiệp | T34: 0907176417 | V34: DN4790204135967
A35: 29 | B35: D1400 | C35: NGUYỄN HỮU ĐỨC | D35: Nam | E35: 23/03/1976 | F35: CÔNG NHÂN | G35: CN/NV thường | I35: =IF($H35="","",IF($H35>=90,"Xuất sắc (A+)",IF($H35>=85,"Giỏi (A)",IF($H35>=80,"Tốt (A-)",IF($H35>=75,"Khá (B+)",IF($H35>=70,"Khá (B)",IF($H35>=65,"Khá (B-)",IF($H35>=60,"Trung bình (C+)",IF($H35>=55,"Trung bình (C)",IF($H35>=50,"Yếu (D)","Không đạt (F)")))))))))) | J35: =IF($H35="","",INDEX(BangTra!$B$2:$D$11,MATCH($H35,BangTra!$A$2:$A$11,1),IF($G35="Đội trưởng",3,IF($G35="Đội phó",2,1)))) | K35: CSKV TT | M35: 023110264 | N35: 14/05/2009 | O35: CA TP.HCM | P35: Tp.HCM | Q35: Số 122/27/77/46 Tôn Đản, phường 8, quận 4, Tp.HCM | R35: Số 152/09, đường Âu Dương Lân, phường 3, quận 8, Tp.HCM | S35: Chứng chỉ sơ cấp ngành Hệ thống điện công nghiệp | T35: 0906801918 | V35: DN4790298122247
A36: 30 | B36: P2645 | C36: NGUYỄN THÀNH PHƯƠNG | D36: Nam | E36: 31/03/1969 | F36: Đội trưởng | G36: Đội trưởng | I36: =IF($H36="","",IF($H36>=90,"Xuất sắc (A+)",IF($H36>=85,"Giỏi (A)",IF($H36>=80,"Tốt (A-)",IF($H36>=75,"Khá (B+)",IF($H36>=70,"Khá (B)",IF($H36>=65,"Khá (B-)",IF($H36>=60,"Trung bình (C+)",IF($H36>=55,"Trung bình (C)",IF($H36>=50,"Yếu (D)","Không đạt (F)")))))))))) | J36: =IF($H36="","",INDEX(BangTra!$B$2:$D$11,MATCH($H36,BangTra!$A$2:$A$11,1),IF($G36="Đội trưởng",3,IF($G36="Đội phó",2,1)))) | K36: CSKV TT | M36: 074069000150 | N36: 13/01/2022 | O36: Cục trưởng cục cảnh sát - Quản lý hành chính về trật tự xã hội | P36: Trà Vinh | Q36: Số 28, đường Phó Đức Chính, phường 1, quận Bình Thạnh, Tp.HCM | S36: Chứng chỉ sơ cấp nghề Kỹ thuật điện (Trường cao đẳng điện lực) | T36: 0908204698 | V36: DN4790298083093
A37: 31 | B37: K2000 | C37: TỐNG VĂN KHANH | D37: Nam | E37: 27/03/1977 | F37: CÔNG NHÂN | G37: CN/NV thường | I37: =IF($H37="","",IF($H37>=90,"Xuất sắc (A+)",IF($H37>=85,"Giỏi (A)",IF($H37>=80,"Tốt (A-)",IF($H37>=75,"Khá (B+)",IF($H37>=70,"Khá (B)",IF($H37>=65,"Khá (B-)",IF($H37>=60,"Trung bình (C+)",IF($H37>=55,"Trung bình (C)",IF($H37>=50,"Yếu (D)","Không đạt (F)")))))))))) | J37: =IF($H37="","",INDEX(BangTra!$B$2:$D$11,MATCH($H37,BangTra!$A$2:$A$11,1),IF($G37="Đội trưởng",3,IF($G37="Đội phó",2,1)))) | K37: CSKV TT | M37: 023071840 | N37: 13/06/2007 | O37: CA TP.HCM | P37: Tp.HCM | Q37: Số 231/44/23, đường Bình Tiên, phường 8, quận 6, Tp.HCM | S37: Chứng chỉ sơ cấp nghề Kỹ thuật điện (Trường cao đẳng điện lực) | T37: 0941208421 | V37: DN4797910300161
A38: 32 | B38: D1370 | C38: TRẦN ĐỨC ĐỊNH | D38: Nam | E38: 02/09/1980 | F38: CÔNG NHÂN | G38: CN/NV thường | I38: =IF($H38="","",IF($H38>=90,"Xuất sắc (A+)",IF($H38>=85,"Giỏi (A)",IF($H38>=80,"Tốt (A-)",IF($H38>=75,"Khá (B+)",IF($H38>=70,"Khá (B)",IF($H38>=65,"Khá (B-)",IF($H38>=60,"Trung bình (C+)",IF($H38>=55,"Trung bình (C)",IF($H38>=50,"Yếu (D)","Không đạt (F)")))))))))) | J38: =IF($H38="","",INDEX(BangTra!$B$2:$D$11,MATCH($H38,BangTra!$A$2:$A$11,1),IF($G38="Đội trưởng",3,IF($G38="Đội phó",2,1)))) | K38: CSKV TT | M38: 037080004417 | N38: 02/04/2021 | O38: Cục trưởng cục cảnh sát - Quản lý hành chính về trật tự xã hội | P38: Ninh Bình | Q38: Số 51/31, đường Lý Phục Man, Khu phố 2, phường Bình Thuận, quận 7, Tp.HCM | S38: Chứng chỉ sơ cấp nghề Kỹ thuật điện (Trường cao đẳng điện lực) | T38: 0931298268 | V38: DN4790203223952
A39: 33 | B39: H1715 | C39: NGUYỄN CHÍ HIẾU | D39: Nam | E39: 06/06/1967 | F39: CÔNG NHÂN | G39: CN/NV thường | I39: =IF($H39="","",IF($H39>=90,"Xuất sắc (A+)",IF($H39>=85,"Giỏi (A)",IF($H39>=80,"Tốt (A-)",IF($H39>=75,"Khá (B+)",IF($H39>=70,"Khá (B)",IF($H39>=65,"Khá (B-)",IF($H39>=60,"Trung bình (C+)",IF($H39>=55,"Trung bình (C)",IF($H39>=50,"Yếu (D)","Không đạt (F)")))))))))) | J39: =IF($H39="","",INDEX(BangTra!$B$2:$D$11,MATCH($H39,BangTra!$A$2:$A$11,1),IF($G39="Đội trưởng",3,IF($G39="Đội phó",2,1)))) | K39: CSKV TT | M39: 092067013467 | N39: 10/05/2021 | O39: Cục trưởng cục cảnh sát - Quản lý hành chính về trật tự xã hội | P39: Đồng Tháp | Q39: Số 231/85, đường Bình Tiên, phường 8, quận 6, Tp.HCM | R39: Số 3/1, đường Lý Đạo Thành, phường 16, quận 8, Tp.HCM | S39: Chứng chỉ sơ cấp nghề Kỹ thuật điện (Trường cao đẳng điện lực) | T39: 0903877451 | V39: DN4790296242077
A40: 34 | B40: H1635 | C40: NGUYỄN VĂN HẬU | D40: Nam | E40: 04/02/1994 | F40: CÔNG NHÂN | G40: CN/NV thường | I40: =IF($H40="","",IF($H40>=90,"Xuất sắc (A+)",IF($H40>=85,"Giỏi (A)",IF($H40>=80,"Tốt (A-)",IF($H40>=75,"Khá (B+)",IF($H40>=70,"Khá (B)",IF($H40>=65,"Khá (B-)",IF($H40>=60,"Trung bình (C+)",IF($H40>=55,"Trung bình (C)",IF($H40>=50,"Yếu (D)","Không đạt (F)")))))))))) | J40: =IF($H40="","",INDEX(BangTra!$B$2:$D$11,MATCH($H40,BangTra!$A$2:$A$11,1),IF($G40="Đội trưởng",3,IF($G40="Đội phó",2,1)))) | K40: CSKV TT | M40: 024995566 | N40: 14/11/2008 | O40: CA TP.HCM | P40: Tp.HCM | Q40: Số 122/27/77/4, đường Tôn Đản, phường 8, quận 4, Tp.HCM | R40: Số 152/09, đường Âu Dương Lân, phường 3, quận 8, Tp HCM | S40: Chứng chỉ sơ cấp nghề Kỹ thuật điện (Trường cao đẳng điện lực) | T40: 0933033754 | V40: DN4797912382519
A41: 35 | B41: P2595 | C41: NGUYỄN BÁ PHƯỚC | D41: Nam | E41: 17/09/1975 | F41: CÔNG NHÂN | G41: CN/NV thường | I41: =IF($H41="","",IF($H41>=90,"Xuất sắc (A+)",IF($H41>=85,"Giỏi (A)",IF($H41>=80,"Tốt (A-)",IF($H41>=75,"Khá (B+)",IF($H41>=70,"Khá (B)",IF($H41>=65,"Khá (B-)",IF($H41>=60,"Trung bình (C+)",IF($H41>=55,"Trung bình (C)",IF($H41>=50,"Yếu (D)","Không đạt (F)")))))))))) | J41: =IF($H41="","",INDEX(BangTra!$B$2:$D$11,MATCH($H41,BangTra!$A$2:$A$11,1),IF($G41="Đội trưởng",3,IF($G41="Đội phó",2,1)))) | K41: CSKV TT | M41: 079075037434 | N41: 12/08/2021 | O41: Cục trưởng cục cảnh sát - Quản lý hành chính về trật tự xã hội | P41: Tp.HCM | Q41: Số 752/19, đường Lạc Long Quân, phường 09, quận Tân Bình, Tp.HCM | S41: Chứng chỉ sơ cấp nghề Kỹ thuật điện (Trường cao đẳng điện lực) | T41: 0908144500 | V41: DN4790296242118
...

Sheet BangTra
A1: MinDiem | B1: CN/NV thường | C1: Đội phó | D1: Đội trưởng
A2: 0 | B2: 1.3 | C2: 1.3 | D2: 1.3
A3: 50 | B3: 1.6 | C3: 1.9 | D3: 2.2
A4: 55 | B4: 1.9 | C4: 2.2 | D4: 2.5
A5: 60 | B5: 2.2 | C5: 2.5 | D5: 2.8
A6: 65 | B6: 2.5 | C6: 2.8 | D6: 3.1
A7: 70 | B7: 2.8 | C7: 3.1 | D7: 3.4
A8: 75 | B8: 3.1 | C8: 3.4 | D8: 3.7
A9: 80 | B9: 3.4 | C9: 3.7 | D9: 4
A10: 85 | B10: 3.7 | C10: 4 | D10: 4.3
A11: 90 | B11: 4 | C11: 4.3 | D11: 4.6
